<sdf version='1.6'>
  <world name='default'>
    <gui fullscreen='0'>
      <camera name='user_camera'>
        <pose frame=''>-0.599335 0.689328 6.77355 3.14159 1.57079 3.14159</pose>
        <view_controller>orbit</view_controller>
        <projection_type>perspective</projection_type>
      </camera>
    </gui>
    <model name='my_ground_plane'>
      <static>1</static>
      <link name='link'>
        <collision name='collision'>
          <geometry>
            <plane>
              <normal>0 0 1</normal>
              <size>4.5 1.6875</size>
            </plane>
          </geometry>
          <surface>
            <friction>
              <ode>
                <mu>100</mu>
                <mu2>50</mu2>
              </ode>
              <torsional>
                <ode/>
              </torsional>
            </friction>
            <contact>
              <ode/>
            </contact>
            <bounce/>
          </surface>
          <max_contacts>10</max_contacts>
        </collision>
        <visual name='visual'>
          <cast_shadows>0</cast_shadows>
          <geometry>
            <plane>
              <normal>0 0 1</normal>
              <size>4.5 1.6875</size>
            </plane>
          </geometry>
          <material>
            <script>
              <uri>model://my_ground_plane/materials/scripts</uri>
              <uri>model://my_ground_plane/materials/textures</uri>
              <name>MyGroundPlane/Image</name>
            </script>
          </material>
        </visual>
        <self_collide>0</self_collide>
        <enable_wind>0</enable_wind>
        <kinematic>0</kinematic>
      </link>
    </model>
    <light name='sun' type='directional'>
      <cast_shadows>1</cast_shadows>
      <pose frame=''>0 0 10 0 -0 0</pose>
      <diffuse>0.8 0.8 0.8 1</diffuse>
      <specular>0.2 0.2 0.2 1</specular>
      <attenuation>
        <range>1000</range>
        <constant>0.9</constant>
        <linear>0.01</linear>
        <quadratic>0.001</quadratic>
      </attenuation>
      <direction>-0.5 0.1 -0.9</direction>
    </light>
    <gravity>0 0 -9.8</gravity>
    <magnetic_field>6e-06 2.3e-05 -4.2e-05</magnetic_field>
    <atmosphere type='adiabatic'/>
    <physics name='default_physics' default='0' type='ode'>
      <max_step_size>0.001</max_step_size>
      <real_time_factor>1</real_time_factor>
      <real_time_update_rate>1000</real_time_update_rate>
    </physics>
    <scene>
      <ambient>0.4 0.4 0.4 1</ambient>
      <background>0.7 0.7 0.7 1</background>
      <shadows>1</shadows>
    </scene>
    <audio>
      <device>default</device>
    </audio>
    <wind/>
    <spherical_coordinates>
      <surface_model>EARTH_WGS84</surface_model>
      <latitude_deg>0</latitude_deg>
      <longitude_deg>0</longitude_deg>
      <elevation>0</elevation>
      <heading_deg>0</heading_deg>
    </spherical_coordinates>
    <model name='car'>
      <link name='base_footprint'>
        <pose frame=''>0 0 0 0 -0 0</pose>
        <inertial>
          <pose frame=''>0.149737 0 0.043684 0 -0 0</pose>
          <mass>3.8</mass>
          <inertia>
            <ixx>0.0186107</ixx>
            <ixy>0</ixy>
            <ixz>0.000136316</ixz>
            <iyy>0.07526</iyy>
            <iyz>0</iyz>
            <izz>0.0885056</izz>
          </inertia>
        </inertial>
        <collision name='base_footprint_fixed_joint_lump__base_center_collision'>
          <pose frame=''>0.15 0 0.04 0 -0 0</pose>
          <geometry>
            <box>
              <size>0.485 0.227 0.05</size>
            </box>
          </geometry>
          <surface>
            <contact>
              <ode/>
            </contact>
            <friction>
              <ode/>
              <torsional>
                <ode/>
              </torsional>
            </friction>
            <bounce/>
          </surface>
          <max_contacts>10</max_contacts>
        </collision>
        <collision name='base_footprint_fixed_joint_lump__laser_frame_collision_1'>
          <pose frame=''>0.14 0 0.18 0 -0 0</pose>
          <geometry>
            <cylinder>
              <length>0.02</length>
              <radius>0.04</radius>
            </cylinder>
          </geometry>
          <surface>
            <contact>
              <ode/>
            </contact>
            <friction>
              <ode/>
              <torsional>
                <ode/>
              </torsional>
            </friction>
            <bounce/>
          </surface>
          <max_contacts>10</max_contacts>
        </collision>
        <visual name='base_footprint_fixed_joint_lump__base_center_visual'>
          <pose frame=''>0.15 0 0.04 0 -0 0</pose>
          <geometry>
            <box>
              <size>0.485 0.227 0.05</size>
            </box>
          </geometry>
          <material>
            <script>
              <name>Gazebo/Orange</name>
              <uri>file://media/materials/scripts/gazebo.material</uri>
            </script>
          </material>
        </visual>
        <visual name='base_footprint_fixed_joint_lump__laser_frame_visual_1'>
          <pose frame=''>0.14 0 0.18 0 -0 0</pose>
          <geometry>
            <cylinder>
              <length>0.02</length>
              <radius>0.04</radius>
            </cylinder>
          </geometry>
          <material>
            <script>
              <name>Gazebo/Black</name>
              <uri>file://media/materials/scripts/gazebo.material</uri>
            </script>
          </material>
        </visual>
        <velocity_decay/>
        <velocity_decay/>
        <velocity_decay/>
        <gravity>1</gravity>
        <velocity_decay/>
        <sensor name='head_hokuyo_sensor' type='ray'>
          <visualize>1</visualize>
          <update_rate>7.5</update_rate>
          <ray>
            <scan>
              <horizontal>
                <samples>360</samples>
                <resolution>1</resolution>
                <min_angle>-3.14159</min_angle>
                <max_angle>3.14159</max_angle>
              </horizontal>
              <vertical>
                <samples>1</samples>
                <min_angle>0</min_angle>
                <max_angle>0</max_angle>
              </vertical>
            </scan>
            <range>
              <min>0.15</min>
              <max>10</max>
              <resolution>0.01</resolution>
            </range>
            <noise>
              <type>gaussian</type>
              <mean>0</mean>
              <stddev>0.01</stddev>
            </noise>
          </ray>
          <plugin name='gazebo_ros_head_hokuyo_controller' filename='libgazebo_ros_laser.so'>
            <topicName>/scan</topicName>
            <frameName>laser_frame</frameName>
            <robotNamespace>/</robotNamespace>
          </plugin>
          <pose frame=''>0.14 0 0.18 0 -0 0</pose>
        </sensor>
        <self_collide>0</self_collide>
        <enable_wind>0</enable_wind>
        <kinematic>0</kinematic>
      </link>
      <link name='steer_fl'>
        <pose frame=''>0.3 -0.1285 0.015 0 -0 0</pose>
        <inertial>
          <pose frame=''>0 0 0 0 -0 0</pose>
          <mass>0.001</mass>
          <inertia>
            <ixx>0.001</ixx>
            <ixy>0</ixy>
            <ixz>0</ixz>
            <iyy>0.001</iyy>
            <iyz>0</iyz>
            <izz>0.001</izz>
          </inertia>
        </inertial>
        <self_collide>0</self_collide>
        <enable_wind>0</enable_wind>
        <kinematic>0</kinematic>
      </link>
      <joint name='fl_steer_joint' type='revolute'>
        <child>steer_fl</child>
        <parent>base_footprint</parent>
        <axis>
          <xyz>0 0 1</xyz>
          <limit>
            <lower>-0.785398</lower>
            <upper>0.785398</upper>
            <effort>0</effort>
            <velocity>0</velocity>
          </limit>
          <dynamics>
            <spring_reference>0</spring_reference>
            <spring_stiffness>0</spring_stiffness>
          </dynamics>
          <use_parent_model_frame>1</use_parent_model_frame>
        </axis>
      </joint>
      <link name='wheel_fl'>
        <pose frame=''>0.3 -0.1285 0.015 1.5708 -0 0</pose>
        <inertial>
          <pose frame=''>0 0 0 0 -0 0</pose>
          <mass>0.056</mass>
          <inertia>
            <ixx>2.66e-05</ixx>
            <ixy>0</ixy>
            <ixz>0</ixz>
            <iyy>2.66e-05</iyy>
            <iyz>0</iyz>
            <izz>4.48e-05</izz>
          </inertia>
        </inertial>
        <collision name='wheel_fl_collision'>
          <pose frame=''>0 0 0 0 -0 0</pose>
          <geometry>
            <cylinder>
              <length>0.03</length>
              <radius>0.04</radius>
            </cylinder>
          </geometry>
          <surface>
            <contact>
              <ode>
                <kp>1e+07</kp>
                <kd>1</kd>
              </ode>
            </contact>
            <friction>
              <ode>
                <mu>1.75</mu>
                <mu2>1.75</mu2>
              </ode>
              <torsional>
                <ode/>
              </torsional>
            </friction>
            <bounce/>
          </surface>
          <max_contacts>10</max_contacts>
        </collision>
        <visual name='wheel_fl_visual'>
          <pose frame=''>0 0 0 0 -0 0</pose>
          <geometry>
            <cylinder>
              <length>0.03</length>
              <radius>0.04</radius>
            </cylinder>
          </geometry>
          <material>
            <script>
              <name>Gazebo/Black</name>
              <uri>file://media/materials/scripts/gazebo.material</uri>
            </script>
          </material>
        </visual>
        <gravity>1</gravity>
        <velocity_decay/>
        <self_collide>0</self_collide>
        <enable_wind>0</enable_wind>
        <kinematic>0</kinematic>
      </link>
      <joint name='fl_speed_joint' type='revolute'>
        <child>wheel_fl</child>
        <parent>steer_fl</parent>
        <axis>
          <xyz>0 1 -0</xyz>
          <limit>
            <lower>-1e+16</lower>
            <upper>1e+16</upper>
          </limit>
          <dynamics>
            <spring_reference>0</spring_reference>
            <spring_stiffness>0</spring_stiffness>
          </dynamics>
          <use_parent_model_frame>1</use_parent_model_frame>
        </axis>
      </joint>
      <link name='steer_fr'>
        <pose frame=''>0.3 0.1285 0.015 0 -0 0</pose>
        <inertial>
          <pose frame=''>0 0 0 0 -0 0</pose>
          <mass>0.001</mass>
          <inertia>
            <ixx>0.001</ixx>
            <ixy>0</ixy>
            <ixz>0</ixz>
            <iyy>0.001</iyy>
            <iyz>0</iyz>
            <izz>0.001</izz>
          </inertia>
        </inertial>
        <self_collide>0</self_collide>
        <enable_wind>0</enable_wind>
        <kinematic>0</kinematic>
      </link>
      <joint name='fr_steer_joint' type='revolute'>
        <child>steer_fr</child>
        <parent>base_footprint</parent>
        <axis>
          <xyz>0 0 1</xyz>
          <limit>
            <lower>-0.785398</lower>
            <upper>0.785398</upper>
            <effort>0</effort>
            <velocity>0</velocity>
          </limit>
          <dynamics>
            <spring_reference>0</spring_reference>
            <spring_stiffness>0</spring_stiffness>
          </dynamics>
          <use_parent_model_frame>1</use_parent_model_frame>
        </axis>
      </joint>
      <link name='wheel_fr'>
        <pose frame=''>0.3 0.1285 0.015 1.5708 -0 0</pose>
        <inertial>
          <pose frame=''>0 0 0 0 -0 0</pose>
          <mass>0.056</mass>
          <inertia>
            <ixx>2.66e-05</ixx>
            <ixy>0</ixy>
            <ixz>0</ixz>
            <iyy>2.66e-05</iyy>
            <iyz>0</iyz>
            <izz>4.48e-05</izz>
          </inertia>
        </inertial>
        <collision name='wheel_fr_collision'>
          <pose frame=''>0 0 0 0 -0 0</pose>
          <geometry>
            <cylinder>
              <length>0.03</length>
              <radius>0.04</radius>
            </cylinder>
          </geometry>
          <surface>
            <contact>
              <ode>
                <kp>1e+07</kp>
                <kd>1</kd>
              </ode>
            </contact>
            <friction>
              <ode>
                <mu>1.75</mu>
                <mu2>1.75</mu2>
              </ode>
              <torsional>
                <ode/>
              </torsional>
            </friction>
            <bounce/>
          </surface>
          <max_contacts>10</max_contacts>
        </collision>
        <visual name='wheel_fr_visual'>
          <pose frame=''>0 0 0 0 -0 0</pose>
          <geometry>
            <cylinder>
              <length>0.03</length>
              <radius>0.04</radius>
            </cylinder>
          </geometry>
          <material>
            <script>
              <name>Gazebo/Black</name>
              <uri>file://media/materials/scripts/gazebo.material</uri>
            </script>
          </material>
        </visual>
        <gravity>1</gravity>
        <velocity_decay/>
        <self_collide>0</self_collide>
        <enable_wind>0</enable_wind>
        <kinematic>0</kinematic>
      </link>
      <joint name='fr_speed_joint' type='revolute'>
        <child>wheel_fr</child>
        <parent>steer_fr</parent>
        <axis>
          <xyz>0 1 -0</xyz>
          <limit>
            <lower>-1e+16</lower>
            <upper>1e+16</upper>
          </limit>
          <dynamics>
            <spring_reference>0</spring_reference>
            <spring_stiffness>0</spring_stiffness>
          </dynamics>
          <use_parent_model_frame>1</use_parent_model_frame>
        </axis>
      </joint>
      <link name='wheel_rl'>
        <pose frame=''>0 -0.1285 0.015 1.5708 -0 0</pose>
        <inertial>
          <pose frame=''>0 0 0 0 -0 0</pose>
          <mass>0.056</mass>
          <inertia>
            <ixx>2.66e-05</ixx>
            <ixy>0</ixy>
            <ixz>0</ixz>
            <iyy>2.66e-05</iyy>
            <iyz>0</iyz>
            <izz>4.48e-05</izz>
          </inertia>
        </inertial>
        <collision name='wheel_rl_collision'>
          <pose frame=''>0 0 0 0 -0 0</pose>
          <geometry>
            <cylinder>
              <length>0.03</length>
              <radius>0.04</radius>
            </cylinder>
          </geometry>
          <surface>
            <contact>
              <ode>
                <kp>1e+07</kp>
                <kd>1</kd>
              </ode>
            </contact>
            <friction>
              <ode>
                <mu>1.75</mu>
                <mu2>1.75</mu2>
              </ode>
              <torsional>
                <ode/>
              </torsional>
            </friction>
            <bounce/>
          </surface>
          <max_contacts>10</max_contacts>
        </collision>
        <visual name='wheel_rl_visual'>
          <pose frame=''>0 0 0 0 -0 0</pose>
          <geometry>
            <cylinder>
              <length>0.03</length>
              <radius>0.04</radius>
            </cylinder>
          </geometry>
          <material>
            <script>
              <name>Gazebo/Black</name>
              <uri>file://media/materials/scripts/gazebo.material</uri>
            </script>
          </material>
        </visual>
        <gravity>1</gravity>
        <velocity_decay/>
        <self_collide>0</self_collide>
        <enable_wind>0</enable_wind>
        <kinematic>0</kinematic>
      </link>
      <joint name='rl_speed_joint' type='revolute'>
        <child>wheel_rl</child>
        <parent>base_footprint</parent>
        <axis>
          <xyz>0 1 -0</xyz>
          <limit>
            <lower>-1e+16</lower>
            <upper>1e+16</upper>
          </limit>
          <dynamics>
            <spring_reference>0</spring_reference>
            <spring_stiffness>0</spring_stiffness>
          </dynamics>
          <use_parent_model_frame>1</use_parent_model_frame>
        </axis>
      </joint>
      <link name='wheel_rr'>
        <pose frame=''>0 0.1285 0.015 1.5708 -0 0</pose>
        <inertial>
          <pose frame=''>0 0 0 0 -0 0</pose>
          <mass>0.056</mass>
          <inertia>
            <ixx>2.66e-05</ixx>
            <ixy>0</ixy>
            <ixz>0</ixz>
            <iyy>2.66e-05</iyy>
            <iyz>0</iyz>
            <izz>4.48e-05</izz>
          </inertia>
        </inertial>
        <collision name='wheel_rr_collision'>
          <pose frame=''>0 0 0 0 -0 0</pose>
          <geometry>
            <cylinder>
              <length>0.03</length>
              <radius>0.04</radius>
            </cylinder>
          </geometry>
          <surface>
            <contact>
              <ode>
                <kp>1e+07</kp>
                <kd>1</kd>
              </ode>
            </contact>
            <friction>
              <ode>
                <mu>1.75</mu>
                <mu2>1.75</mu2>
              </ode>
              <torsional>
                <ode/>
              </torsional>
            </friction>
            <bounce/>
          </surface>
          <max_contacts>10</max_contacts>
        </collision>
        <visual name='wheel_rr_visual'>
          <pose frame=''>0 0 0 0 -0 0</pose>
          <geometry>
            <cylinder>
              <length>0.03</length>
              <radius>0.04</radius>
            </cylinder>
          </geometry>
          <material>
            <script>
              <name>Gazebo/Black</name>
              <uri>file://media/materials/scripts/gazebo.material</uri>
            </script>
          </material>
        </visual>
        <gravity>1</gravity>
        <velocity_decay/>
        <self_collide>0</self_collide>
        <enable_wind>0</enable_wind>
        <kinematic>0</kinematic>
      </link>
      <joint name='rr_speed_joint' type='revolute'>
        <child>wheel_rr</child>
        <parent>base_footprint</parent>
        <axis>
          <xyz>0 1 -0</xyz>
          <limit>
            <lower>-1e+16</lower>
            <upper>1e+16</upper>
          </limit>
          <dynamics>
            <spring_reference>0</spring_reference>
            <spring_stiffness>0</spring_stiffness>
          </dynamics>
          <use_parent_model_frame>1</use_parent_model_frame>
        </axis>
      </joint>
      <static>0</static>
      <plugin name='wr8_interface_plugin' filename='libwr8_interface_plugin.so'>
        <robotName/>
        <pubTf>1</pubTf>
        <tfFreq>100.0</tfFreq>
        <maxSteerRad>0.523598775598</maxSteerRad>
        <wheelbase>0.3</wheelbase>
        <wheelRadius>0.04</wheelRadius>
        <trackWidth>0.257</trackWidth>
        <robotNamespace>/</robotNamespace>
      </plugin>
      <plugin name='joint_state_publisher' filename='libgazebo_ros_joint_state_publisher.so'>
        <robotNamespace/>
        <jointName>fl_steer_joint, fr_steer_joint, fl_speed_joint, fr_speed_joint, rl_speed_joint, rr_speed_joint</jointName>
        <updateRate>100</updateRate>
        <alwaysOn>1</alwaysOn>
      </plugin>
      <pose frame=''>0 0 0.5 0 -0 3.139</pose>
    </model>
    <model name='unit_box'>
      <pose frame=''>-2.72848 0.451168 0.5 0 -0 0</pose>
      <link name='link'>
        <inertial>
          <mass>1</mass>
          <inertia>
            <ixx>0.166667</ixx>
            <ixy>0</ixy>
            <ixz>0</ixz>
            <iyy>0.166667</iyy>
            <iyz>0</iyz>
            <izz>0.166667</izz>
          </inertia>
        </inertial>
        <collision name='collision'>
          <geometry>
            <box>
              <size>1 1 1</size>
            </box>
          </geometry>
          <max_contacts>10</max_contacts>
          <surface>
            <contact>
              <ode/>
            </contact>
            <bounce/>
            <friction>
              <torsional>
                <ode/>
              </torsional>
              <ode/>
            </friction>
          </surface>
        </collision>
        <visual name='visual'>
          <geometry>
            <box>
              <size>1 1 1</size>
            </box>
          </geometry>
          <material>
            <script>
              <name>Gazebo/Grey</name>
              <uri>file://media/materials/scripts/gazebo.material</uri>
            </script>
          </material>
        </visual>
        <self_collide>0</self_collide>
        <enable_wind>0</enable_wind>
        <kinematic>0</kinematic>
      </link>
    </model>
    <model name='unit_box_0'>
      <pose frame=''>-1.91348 1.33316 0.5 0 -0 0</pose>
      <link name='link'>
        <inertial>
          <mass>1</mass>
          <inertia>
            <ixx>0.166667</ixx>
            <ixy>0</ixy>
            <ixz>0</ixz>
            <iyy>0.166667</iyy>
            <iyz>0</iyz>
            <izz>0.166667</izz>
          </inertia>
        </inertial>
        <collision name='collision'>
          <geometry>
            <box>
              <size>1 1 1</size>
            </box>
          </geometry>
          <max_contacts>10</max_contacts>
          <surface>
            <contact>
              <ode/>
            </contact>
            <bounce/>
            <friction>
              <torsional>
                <ode/>
              </torsional>
              <ode/>
            </friction>
          </surface>
        </collision>
        <visual name='visual'>
          <geometry>
            <box>
              <size>1 1 1</size>
            </box>
          </geometry>
          <material>
            <script>
              <name>Gazebo/Grey</name>
              <uri>file://media/materials/scripts/gazebo.material</uri>
            </script>
          </material>
        </visual>
        <self_collide>0</self_collide>
        <enable_wind>0</enable_wind>
        <kinematic>0</kinematic>
      </link>
    </model>
    <model name='unit_box_clone'>
      <pose frame=''>2.89505 -0.219928 0.499985 1.5e-05 -0 -0.012558</pose>
      <link name='link'>
        <inertial>
          <mass>1</mass>
          <inertia>
            <ixx>0.166667</ixx>
            <ixy>0</ixy>
            <ixz>0</ixz>
            <iyy>0.166667</iyy>
            <iyz>0</iyz>
            <izz>0.166667</izz>
          </inertia>
        </inertial>
        <collision name='collision'>
          <geometry>
            <box>
              <size>1 2.01504 1</size>
            </box>
          </geometry>
          <max_contacts>10</max_contacts>
          <surface>
            <contact>
              <ode/>
            </contact>
            <bounce/>
            <friction>
              <torsional>
                <ode/>
              </torsional>
              <ode/>
            </friction>
          </surface>
        </collision>
        <visual name='visual'>
          <geometry>
            <box>
              <size>1 2.01504 1</size>
            </box>
          </geometry>
          <material>
            <script>
              <name>Gazebo/Grey</name>
              <uri>file://media/materials/scripts/gazebo.material</uri>
            </script>
          </material>
        </visual>
        <self_collide>0</self_collide>
        <enable_wind>0</enable_wind>
        <kinematic>0</kinematic>
      </link>
    </model>
    <model name='unit_box_0_clone'>
      <pose frame=''>0.107622 -1.74744 0.498528 0 0.000638 -2.6e-05</pose>
      <link name='link'>
        <inertial>
          <mass>1</mass>
          <inertia>
            <ixx>0.166667</ixx>
            <ixy>0</ixy>
            <ixz>0</ixz>
            <iyy>0.166667</iyy>
            <iyz>0</iyz>
            <izz>0.166667</izz>
          </inertia>
        </inertial>
        <collision name='collision'>
          <geometry>
            <box>
              <size>4.61832 1 1</size>
            </box>
          </geometry>
          <max_contacts>10</max_contacts>
          <surface>
            <contact>
              <ode/>
            </contact>
            <bounce/>
            <friction>
              <torsional>
                <ode/>
              </torsional>
              <ode/>
            </friction>
          </surface>
        </collision>
        <visual name='visual'>
          <geometry>
            <box>
              <size>4.61832 1 1</size>
            </box>
          </geometry>
          <material>
            <script>
              <name>Gazebo/Grey</name>
              <uri>file://media/materials/scripts/gazebo.material</uri>
            </script>
          </material>
        </visual>
        <self_collide>0</self_collide>
        <enable_wind>0</enable_wind>
        <kinematic>0</kinematic>
      </link>
    </model>
    <state world_name='default'>
      <sim_time>2625 500000000</sim_time>
      <real_time>4639 885425755</real_time>
      <wall_time>1589135490 984022064</wall_time>
      <iterations>2625500</iterations>
      <model name='car'>
        <pose frame=''>0.505144 0.185782 0.024999 -1e-06 0.000837 0.0773</pose>
        <scale>1 1 1</scale>
        <link name='base_footprint'>
          <pose frame=''>0.505144 0.185782 0.024999 -1e-06 0.000837 0.0773</pose>
          <velocity>2e-06 -1.2e-05 3e-06 -0.000235 -1.7e-05 -3.8e-05</velocity>
          <acceleration>-0.001204 0.013898 -0.010702 -0.766165 -0.051895 0.062903</acceleration>
          <wrench>-0.004577 0.052812 -0.040667 0 -0 0</wrench>
        </link>
        <link name='steer_fl'>
          <pose frame=''>0.814183 0.080834 0.040098 -2e-06 0.000837 0.0773</pose>
          <velocity>-0.000141 0.001729 -0.001258 -0.001186 -8.7e-05 -8.2e-05</velocity>
          <acceleration>-0.192611 2.30879 -1.33752 -2.03869 -0.100265 0.07636</acceleration>
          <wrench>-0.000193 0.002309 -0.001338 0 -0 0</wrench>
        </link>
        <link name='steer_fr'>
          <pose frame=''>0.794336 0.337066 0.040099 3e-06 0.000838 0.0773</pose>
          <velocity>5.2e-05 -0.000549 6.8e-05 0.00014 9e-06 -0.000324</velocity>
          <acceleration>-0.02683 0.601951 -1.10231 -0.98917 -0.025661 -0.435951</acceleration>
          <wrench>-2.7e-05 0.000602 -0.001102 0 -0 0</wrench>
        </link>
        <link name='wheel_fl'>
          <pose frame=''>0.814183 0.080834 0.039999 1.57075 0.95005 0.077259</pose>
          <velocity>-0.000104 0.001285 -0.000899 -0.032267 -0.002621 -4.5e-05</velocity>
          <acceleration>-0.139982 1.72799 -0.94514 -2.51003 0.313053 3.13943</acceleration>
          <wrench>-0.007839 0.096767 -0.052928 0 -0 0</wrench>
        </link>
        <link name='wheel_fr'>
          <pose frame=''>0.794337 0.337066 0.04 1.5708 0.774337 0.077303</pose>
          <velocity>4e-05 -0.000419 4.3e-05 0.01047 0.001018 -0.000106</velocity>
          <acceleration>-0.022261 0.442381 -0.821065 1.51587 -0.672695 -0.224016</acceleration>
          <wrench>-0.001247 0.024773 -0.04598 0 -0 0</wrench>
        </link>
        <link name='wheel_rl'>
          <pose frame=''>0.51508 0.057668 0.04 1.57083 0.977427 0.077321</pose>
          <velocity>-4e-06 -5e-06 0 0.000118 -0.000105 -1.8e-05</velocity>
          <acceleration>0.006989 -0.013151 0.062605 -0.417169 -0.070071 0.139143</acceleration>
          <wrench>0.000391 -0.000736 0.003506 0 -0 0</wrench>
        </link>
        <link name='wheel_rr'>
          <pose frame=''>0.495233 0.3139 0.04 1.57082 -0.871818 0.077281</pose>
          <velocity>7e-06 -7e-06 4e-06 0.000175 0.000174 -1.7e-05</velocity>
          <acceleration>-0.007618 -0.017452 -0.069482 -0.350938 0.098276 0.140715</acceleration>
          <wrench>-0.000427 -0.000977 -0.003891 0 -0 0</wrench>
        </link>
      </model>
      <model name='my_ground_plane'>
        <pose frame=''>0 0 0 0 -0 0</pose>
        <scale>1 1 1</scale>
        <link name='link'>
          <pose frame=''>0 0 0 0 -0 0</pose>
          <velocity>0 0 0 0 -0 0</velocity>
          <acceleration>0 0 0 0 -0 0</acceleration>
          <wrench>0 0 0 0 -0 0</wrench>
        </link>
      </model>
      <model name='unit_box'>
        <pose frame=''>-2.77056 -0.067995 0.499985 -1.5e-05 -0 -0.012076</pose>
        <scale>1 2.01504 1</scale>
        <link name='link'>
          <pose frame=''>-2.77056 -0.067995 0.499985 -1.5e-05 -0 -0.012076</pose>
          <velocity>0 0 0 0 -0 0</velocity>
          <acceleration>0.126337 9.8 -0 1.57992 0.360293 0</acceleration>
          <wrench>0.126337 9.8 -0 0 -0 0</wrench>
        </link>
      </model>
      <model name='unit_box_0'>
        <pose frame=''>0.09546 1.38021 0.498528 0 -0.000638 7e-06</pose>
        <scale>4.61832 1 1</scale>
        <link name='link'>
          <pose frame=''>0.09546 1.38021 0.498528 0 -0.000638 7e-06</pose>
          <velocity>-0.0049 -0 -0.112684 0 -0.053137 0</velocity>
          <acceleration>-9.8 -1e-06 0 1.9e-05 0.541028 0</acceleration>
          <wrench>-9.8 -1e-06 0 0 -0 0</wrench>
        </link>
      </model>
      <model name='unit_box_0_clone'>
        <pose frame=''>0.064366 -1.32696 0.498528 0 -0.000638 7e-06</pose>
        <scale>1 1 1</scale>
        <link name='link'>
          <pose frame=''>0.064366 -1.32696 0.498528 0 -0.000638 7e-06</pose>
          <velocity>-0.0049 -0 -0.112684 0 -0.053137 0</velocity>
          <acceleration>-9.8 -1e-06 -0 1.9e-05 0.541086 0</acceleration>
          <wrench>-9.8 -1e-06 -0 0 -0 0</wrench>
        </link>
      </model>
      <model name='unit_box_clone'>
        <pose frame=''>2.76567 0.017247 0.5 0 -0 0.007396</pose>
        <scale>1 0.812801 1</scale>
        <link name='link'>
          <pose frame=''>2.76567 0.017247 0.5 0 -0 0.007396</pose>
          <velocity>0 0 0 0 -0 0</velocity>
          <acceleration>-9.57698 -0.115168 9.59277 0.229708 -0.313121 -0.000413</acceleration>
          <wrench>-9.57698 -0.115168 9.59277 0 -0 0</wrench>
        </link>
      </model>
      <light name='sun'>
        <pose frame=''>0 0 10 0 -0 0</pose>
      </light>
    </state>
  </world>
</sdf>
