<sdf version='1.6'>
  <world name='default'>
    <gui fullscreen='0'>
      <camera name='user_camera'>
        <pose frame=''>-0.352905 1.20922 18.349 3.14159 1.57079 3.14159</pose>
        <view_controller>orbit</view_controller>
        <projection_type>perspective</projection_type>
      </camera>
    </gui>
    <model name='my_ground_plane'>
      <static>1</static>
      <link name='link'>
        <collision name='collision'>
          <geometry>
            <plane>
              <normal>0 0 1</normal>
              <size>4.5 1.6875</size>
            </plane>
          </geometry>
          <surface>
            <friction>
              <ode>
                <mu>100</mu>
                <mu2>50</mu2>
              </ode>
              <torsional>
                <ode/>
              </torsional>
            </friction>
            <contact>
              <ode/>
            </contact>
            <bounce/>
          </surface>
          <max_contacts>10</max_contacts>
        </collision>
        <visual name='visual'>
          <cast_shadows>0</cast_shadows>
          <geometry>
            <plane>
              <normal>0 0 1</normal>
              <size>4.5 1.6875</size>
            </plane>
          </geometry>
          <material>
            <script>
              <uri>model://my_ground_plane/materials/scripts</uri>
              <uri>model://my_ground_plane/materials/textures</uri>
              <name>MyGroundPlane/Image</name>
            </script>
          </material>
        </visual>
        <pose frame=''>1.529 -0.219 0.5 0 -0 3.139</pose>
        <self_collide>0</self_collide>
        <enable_wind>0</enable_wind>
        <kinematic>0</kinematic>
      </link>
    </model>
    <light name='sun' type='directional'>
      <cast_shadows>1</cast_shadows>
      <pose frame=''>0 0 10 0 -0 0</pose>
      <diffuse>0.8 0.8 0.8 1</diffuse>
      <specular>0.2 0.2 0.2 1</specular>
      <attenuation>
        <range>1000</range>
        <constant>0.9</constant>
        <linear>0.01</linear>
        <quadratic>0.001</quadratic>
      </attenuation>
      <direction>-0.5 0.1 -0.9</direction>
    </light>
    <gravity>0 0 -9.8</gravity>
    <magnetic_field>6e-06 2.3e-05 -4.2e-05</magnetic_field>
    <atmosphere type='adiabatic'/>
    <physics name='default_physics' default='0' type='ode'>
      <max_step_size>0.001</max_step_size>
      <real_time_factor>1</real_time_factor>
      <real_time_update_rate>1000</real_time_update_rate>
    </physics>
    <scene>
      <ambient>0.4 0.4 0.4 1</ambient>
      <background>0.7 0.7 0.7 1</background>
      <shadows>1</shadows>
    </scene>
    <audio>
      <device>default</device>
    </audio>
    <wind/>
    <spherical_coordinates>
      <surface_model>EARTH_WGS84</surface_model>
      <latitude_deg>0</latitude_deg>
      <longitude_deg>0</longitude_deg>
      <elevation>0</elevation>
      <heading_deg>0</heading_deg>
    </spherical_coordinates>
    <model name='car'>
      <link name='base_footprint'>
        <pose frame=''>0 0 0 0 -0 0</pose>
        <inertial>
          <pose frame=''>0.149737 0 0.043684 0 -0 0</pose>
          <mass>3.8</mass>
          <inertia>
            <ixx>0.0186107</ixx>
            <ixy>0</ixy>
            <ixz>0.000136316</ixz>
            <iyy>0.07526</iyy>
            <iyz>0</iyz>
            <izz>0.0885056</izz>
          </inertia>
        </inertial>
        <collision name='base_footprint_fixed_joint_lump__base_center_collision'>
          <pose frame=''>0.15 0 0.04 0 -0 0</pose>
          <geometry>
            <box>
              <size>0.485 0.227 0.05</size>
            </box>
          </geometry>
          <surface>
            <contact>
              <ode/>
            </contact>
            <friction>
              <ode/>
              <torsional>
                <ode/>
              </torsional>
            </friction>
            <bounce/>
          </surface>
          <max_contacts>10</max_contacts>
        </collision>
        <collision name='base_footprint_fixed_joint_lump__laser_frame_collision_1'>
          <pose frame=''>0.14 0 0.18 0 -0 0</pose>
          <geometry>
            <cylinder>
              <length>0.02</length>
              <radius>0.04</radius>
            </cylinder>
          </geometry>
          <surface>
            <contact>
              <ode/>
            </contact>
            <friction>
              <ode/>
              <torsional>
                <ode/>
              </torsional>
            </friction>
            <bounce/>
          </surface>
          <max_contacts>10</max_contacts>
        </collision>
        <visual name='base_footprint_fixed_joint_lump__base_center_visual'>
          <pose frame=''>0.15 0 0.04 0 -0 0</pose>
          <geometry>
            <box>
              <size>0.485 0.227 0.05</size>
            </box>
          </geometry>
          <material>
            <script>
              <name>Gazebo/Orange</name>
              <uri>file://media/materials/scripts/gazebo.material</uri>
            </script>
          </material>
        </visual>
        <visual name='base_footprint_fixed_joint_lump__laser_frame_visual_1'>
          <pose frame=''>0.14 0 0.18 0 -0 0</pose>
          <geometry>
            <cylinder>
              <length>0.02</length>
              <radius>0.04</radius>
            </cylinder>
          </geometry>
          <material>
            <script>
              <name>Gazebo/Black</name>
              <uri>file://media/materials/scripts/gazebo.material</uri>
            </script>
          </material>
        </visual>
        <velocity_decay/>
        <velocity_decay/>
        <velocity_decay/>
        <gravity>1</gravity>
        <velocity_decay/>
        <sensor name='head_hokuyo_sensor' type='ray'>
          <visualize>1</visualize>
          <update_rate>7.5</update_rate>
          <ray>
            <scan>
              <horizontal>
                <samples>360</samples>
                <resolution>1</resolution>
                <min_angle>-3.14159</min_angle>
                <max_angle>3.14159</max_angle>
              </horizontal>
              <vertical>
                <samples>1</samples>
                <min_angle>0</min_angle>
                <max_angle>0</max_angle>
              </vertical>
            </scan>
            <range>
              <min>0.15</min>
              <max>10</max>
              <resolution>0.01</resolution>
            </range>
            <noise>
              <type>gaussian</type>
              <mean>0</mean>
              <stddev>0.01</stddev>
            </noise>
          </ray>
          <plugin name='gazebo_ros_head_hokuyo_controller' filename='libgazebo_ros_laser.so'>
            <topicName>/scan</topicName>
            <frameName>laser_frame</frameName>
            <robotNamespace>/</robotNamespace>
          </plugin>
          <pose frame=''>0.14 0 0.18 0 -0 0</pose>
        </sensor>
        <self_collide>0</self_collide>
        <enable_wind>0</enable_wind>
        <kinematic>0</kinematic>
      </link>
      <link name='steer_fl'>
        <pose frame=''>0.3 -0.1285 0.015 0 -0 0</pose>
        <inertial>
          <pose frame=''>0 0 0 0 -0 0</pose>
          <mass>0.001</mass>
          <inertia>
            <ixx>0.001</ixx>
            <ixy>0</ixy>
            <ixz>0</ixz>
            <iyy>0.001</iyy>
            <iyz>0</iyz>
            <izz>0.001</izz>
          </inertia>
        </inertial>
        <self_collide>0</self_collide>
        <enable_wind>0</enable_wind>
        <kinematic>0</kinematic>
      </link>
      <joint name='fl_steer_joint' type='revolute'>
        <child>steer_fl</child>
        <parent>base_footprint</parent>
        <axis>
          <xyz>0 0 1</xyz>
          <limit>
            <lower>-0.785398</lower>
            <upper>0.785398</upper>
            <effort>0</effort>
            <velocity>0</velocity>
          </limit>
          <dynamics>
            <spring_reference>0</spring_reference>
            <spring_stiffness>0</spring_stiffness>
          </dynamics>
          <use_parent_model_frame>1</use_parent_model_frame>
        </axis>
      </joint>
      <link name='wheel_fl'>
        <pose frame=''>0.3 -0.1285 0.015 1.5708 -0 0</pose>
        <inertial>
          <pose frame=''>0 0 0 0 -0 0</pose>
          <mass>0.056</mass>
          <inertia>
            <ixx>2.66e-05</ixx>
            <ixy>0</ixy>
            <ixz>0</ixz>
            <iyy>2.66e-05</iyy>
            <iyz>0</iyz>
            <izz>4.48e-05</izz>
          </inertia>
        </inertial>
        <collision name='wheel_fl_collision'>
          <pose frame=''>0 0 0 0 -0 0</pose>
          <geometry>
            <cylinder>
              <length>0.03</length>
              <radius>0.04</radius>
            </cylinder>
          </geometry>
          <surface>
            <contact>
              <ode>
                <kp>1e+07</kp>
                <kd>1</kd>
              </ode>
            </contact>
            <friction>
              <ode>
                <mu>1.75</mu>
                <mu2>1.75</mu2>
              </ode>
              <torsional>
                <ode/>
              </torsional>
            </friction>
            <bounce/>
          </surface>
          <max_contacts>10</max_contacts>
        </collision>
        <visual name='wheel_fl_visual'>
          <pose frame=''>0 0 0 0 -0 0</pose>
          <geometry>
            <cylinder>
              <length>0.03</length>
              <radius>0.04</radius>
            </cylinder>
          </geometry>
          <material>
            <script>
              <name>Gazebo/Black</name>
              <uri>file://media/materials/scripts/gazebo.material</uri>
            </script>
          </material>
        </visual>
        <gravity>1</gravity>
        <velocity_decay/>
        <self_collide>0</self_collide>
        <enable_wind>0</enable_wind>
        <kinematic>0</kinematic>
      </link>
      <joint name='fl_speed_joint' type='revolute'>
        <child>wheel_fl</child>
        <parent>steer_fl</parent>
        <axis>
          <xyz>0 1 -0</xyz>
          <limit>
            <lower>-1e+16</lower>
            <upper>1e+16</upper>
          </limit>
          <dynamics>
            <spring_reference>0</spring_reference>
            <spring_stiffness>0</spring_stiffness>
          </dynamics>
          <use_parent_model_frame>1</use_parent_model_frame>
        </axis>
      </joint>
      <link name='steer_fr'>
        <pose frame=''>0.3 0.1285 0.015 0 -0 0</pose>
        <inertial>
          <pose frame=''>0 0 0 0 -0 0</pose>
          <mass>0.001</mass>
          <inertia>
            <ixx>0.001</ixx>
            <ixy>0</ixy>
            <ixz>0</ixz>
            <iyy>0.001</iyy>
            <iyz>0</iyz>
            <izz>0.001</izz>
          </inertia>
        </inertial>
        <self_collide>0</self_collide>
        <enable_wind>0</enable_wind>
        <kinematic>0</kinematic>
      </link>
      <joint name='fr_steer_joint' type='revolute'>
        <child>steer_fr</child>
        <parent>base_footprint</parent>
        <axis>
          <xyz>0 0 1</xyz>
          <limit>
            <lower>-0.785398</lower>
            <upper>0.785398</upper>
            <effort>0</effort>
            <velocity>0</velocity>
          </limit>
          <dynamics>
            <spring_reference>0</spring_reference>
            <spring_stiffness>0</spring_stiffness>
          </dynamics>
          <use_parent_model_frame>1</use_parent_model_frame>
        </axis>
      </joint>
      <link name='wheel_fr'>
        <pose frame=''>0.3 0.1285 0.015 1.5708 -0 0</pose>
        <inertial>
          <pose frame=''>0 0 0 0 -0 0</pose>
          <mass>0.056</mass>
          <inertia>
            <ixx>2.66e-05</ixx>
            <ixy>0</ixy>
            <ixz>0</ixz>
            <iyy>2.66e-05</iyy>
            <iyz>0</iyz>
            <izz>4.48e-05</izz>
          </inertia>
        </inertial>
        <collision name='wheel_fr_collision'>
          <pose frame=''>0 0 0 0 -0 0</pose>
          <geometry>
            <cylinder>
              <length>0.03</length>
              <radius>0.04</radius>
            </cylinder>
          </geometry>
          <surface>
            <contact>
              <ode>
                <kp>1e+07</kp>
                <kd>1</kd>
              </ode>
            </contact>
            <friction>
              <ode>
                <mu>1.75</mu>
                <mu2>1.75</mu2>
              </ode>
              <torsional>
                <ode/>
              </torsional>
            </friction>
            <bounce/>
          </surface>
          <max_contacts>10</max_contacts>
        </collision>
        <visual name='wheel_fr_visual'>
          <pose frame=''>0 0 0 0 -0 0</pose>
          <geometry>
            <cylinder>
              <length>0.03</length>
              <radius>0.04</radius>
            </cylinder>
          </geometry>
          <material>
            <script>
              <name>Gazebo/Black</name>
              <uri>file://media/materials/scripts/gazebo.material</uri>
            </script>
          </material>
        </visual>
        <gravity>1</gravity>
        <velocity_decay/>
        <self_collide>0</self_collide>
        <enable_wind>0</enable_wind>
        <kinematic>0</kinematic>
      </link>
      <joint name='fr_speed_joint' type='revolute'>
        <child>wheel_fr</child>
        <parent>steer_fr</parent>
        <axis>
          <xyz>0 1 -0</xyz>
          <limit>
            <lower>-1e+16</lower>
            <upper>1e+16</upper>
          </limit>
          <dynamics>
            <spring_reference>0</spring_reference>
            <spring_stiffness>0</spring_stiffness>
          </dynamics>
          <use_parent_model_frame>1</use_parent_model_frame>
        </axis>
      </joint>
      <link name='wheel_rl'>
        <pose frame=''>0 -0.1285 0.015 1.5708 -0 0</pose>
        <inertial>
          <pose frame=''>0 0 0 0 -0 0</pose>
          <mass>0.056</mass>
          <inertia>
            <ixx>2.66e-05</ixx>
            <ixy>0</ixy>
            <ixz>0</ixz>
            <iyy>2.66e-05</iyy>
            <iyz>0</iyz>
            <izz>4.48e-05</izz>
          </inertia>
        </inertial>
        <collision name='wheel_rl_collision'>
          <pose frame=''>0 0 0 0 -0 0</pose>
          <geometry>
            <cylinder>
              <length>0.03</length>
              <radius>0.04</radius>
            </cylinder>
          </geometry>
          <surface>
            <contact>
              <ode>
                <kp>1e+07</kp>
                <kd>1</kd>
              </ode>
            </contact>
            <friction>
              <ode>
                <mu>1.75</mu>
                <mu2>1.75</mu2>
              </ode>
              <torsional>
                <ode/>
              </torsional>
            </friction>
            <bounce/>
          </surface>
          <max_contacts>10</max_contacts>
        </collision>
        <visual name='wheel_rl_visual'>
          <pose frame=''>0 0 0 0 -0 0</pose>
          <geometry>
            <cylinder>
              <length>0.03</length>
              <radius>0.04</radius>
            </cylinder>
          </geometry>
          <material>
            <script>
              <name>Gazebo/Black</name>
              <uri>file://media/materials/scripts/gazebo.material</uri>
            </script>
          </material>
        </visual>
        <gravity>1</gravity>
        <velocity_decay/>
        <self_collide>0</self_collide>
        <enable_wind>0</enable_wind>
        <kinematic>0</kinematic>
      </link>
      <joint name='rl_speed_joint' type='revolute'>
        <child>wheel_rl</child>
        <parent>base_footprint</parent>
        <axis>
          <xyz>0 1 -0</xyz>
          <limit>
            <lower>-1e+16</lower>
            <upper>1e+16</upper>
          </limit>
          <dynamics>
            <spring_reference>0</spring_reference>
            <spring_stiffness>0</spring_stiffness>
          </dynamics>
          <use_parent_model_frame>1</use_parent_model_frame>
        </axis>
      </joint>
      <link name='wheel_rr'>
        <pose frame=''>0 0.1285 0.015 1.5708 -0 0</pose>
        <inertial>
          <pose frame=''>0 0 0 0 -0 0</pose>
          <mass>0.056</mass>
          <inertia>
            <ixx>2.66e-05</ixx>
            <ixy>0</ixy>
            <ixz>0</ixz>
            <iyy>2.66e-05</iyy>
            <iyz>0</iyz>
            <izz>4.48e-05</izz>
          </inertia>
        </inertial>
        <collision name='wheel_rr_collision'>
          <pose frame=''>0 0 0 0 -0 0</pose>
          <geometry>
            <cylinder>
              <length>0.03</length>
              <radius>0.04</radius>
            </cylinder>
          </geometry>
          <surface>
            <contact>
              <ode>
                <kp>1e+07</kp>
                <kd>1</kd>
              </ode>
            </contact>
            <friction>
              <ode>
                <mu>1.75</mu>
                <mu2>1.75</mu2>
              </ode>
              <torsional>
                <ode/>
              </torsional>
            </friction>
            <bounce/>
          </surface>
          <max_contacts>10</max_contacts>
        </collision>
        <visual name='wheel_rr_visual'>
          <pose frame=''>0 0 0 0 -0 0</pose>
          <geometry>
            <cylinder>
              <length>0.03</length>
              <radius>0.04</radius>
            </cylinder>
          </geometry>
          <material>
            <script>
              <name>Gazebo/Black</name>
              <uri>file://media/materials/scripts/gazebo.material</uri>
            </script>
          </material>
        </visual>
        <gravity>1</gravity>
        <velocity_decay/>
        <self_collide>0</self_collide>
        <enable_wind>0</enable_wind>
        <kinematic>0</kinematic>
      </link>
      <joint name='rr_speed_joint' type='revolute'>
        <child>wheel_rr</child>
        <parent>base_footprint</parent>
        <axis>
          <xyz>0 1 -0</xyz>
          <limit>
            <lower>-1e+16</lower>
            <upper>1e+16</upper>
          </limit>
          <dynamics>
            <spring_reference>0</spring_reference>
            <spring_stiffness>0</spring_stiffness>
          </dynamics>
          <use_parent_model_frame>1</use_parent_model_frame>
        </axis>
      </joint>
      <static>0</static>
      <plugin name='wr8_interface_plugin' filename='libwr8_interface_plugin.so'>
        <robotName/>
        <pubTf>1</pubTf>
        <tfFreq>100.0</tfFreq>
        <maxSteerRad>0.523598775598</maxSteerRad>
        <wheelbase>0.3</wheelbase>
        <wheelRadius>0.04</wheelRadius>
        <trackWidth>0.257</trackWidth>
        <robotNamespace>/</robotNamespace>
      </plugin>
      <plugin name='joint_state_publisher' filename='libgazebo_ros_joint_state_publisher.so'>
        <robotNamespace/>
        <jointName>fl_steer_joint, fr_steer_joint, fl_speed_joint, fr_speed_joint, rl_speed_joint, rr_speed_joint</jointName>
        <updateRate>100</updateRate>
        <alwaysOn>1</alwaysOn>
      </plugin>
      <pose frame=''>0 0 0.5 0 -0 3.139</pose>
    </model>
    <model name='unit_box'>
      <pose frame=''>-0.385586 1.16329 0.5 0 -0 0</pose>
      <link name='link'>
        <inertial>
          <mass>1</mass>
          <inertia>
            <ixx>0.166667</ixx>
            <ixy>0</ixy>
            <ixz>0</ixz>
            <iyy>0.166667</iyy>
            <iyz>0</iyz>
            <izz>0.166667</izz>
          </inertia>
        </inertial>
        <collision name='collision'>
          <geometry>
            <box>
              <size>0.999999 1 1</size>
            </box>
          </geometry>
          <max_contacts>10</max_contacts>
          <surface>
            <contact>
              <ode/>
            </contact>
            <bounce/>
            <friction>
              <torsional>
                <ode/>
              </torsional>
              <ode/>
            </friction>
          </surface>
        </collision>
        <visual name='visual'>
          <geometry>
            <box>
              <size>0.999999 1 1</size>
            </box>
          </geometry>
          <material>
            <script>
              <name>Gazebo/Grey</name>
              <uri>file://media/materials/scripts/gazebo.material</uri>
            </script>
          </material>
        </visual>
        <self_collide>0</self_collide>
        <enable_wind>0</enable_wind>
        <kinematic>0</kinematic>
      </link>
    </model>
    <model name='unit_box_clone'>
      <pose frame=''>1.86977 -1.55741 1 2e-06 1e-06 1.9e-05</pose>
      <link name='link'>
        <inertial>
          <mass>1</mass>
          <inertia>
            <ixx>0.166667</ixx>
            <ixy>0</ixy>
            <ixz>0</ixz>
            <iyy>0.166667</iyy>
            <iyz>0</iyz>
            <izz>0.166667</izz>
          </inertia>
        </inertial>
        <collision name='collision'>
          <geometry>
            <box>
              <size>5.14265 1 1</size>
            </box>
          </geometry>
          <max_contacts>10</max_contacts>
          <surface>
            <contact>
              <ode/>
            </contact>
            <bounce/>
            <friction>
              <torsional>
                <ode/>
              </torsional>
              <ode/>
            </friction>
          </surface>
        </collision>
        <visual name='visual'>
          <geometry>
            <box>
              <size>5.14265 1 1</size>
            </box>
          </geometry>
          <material>
            <script>
              <name>Gazebo/Grey</name>
              <uri>file://media/materials/scripts/gazebo.material</uri>
            </script>
          </material>
        </visual>
        <self_collide>0</self_collide>
        <enable_wind>0</enable_wind>
        <kinematic>0</kinematic>
      </link>
    </model>
    <model name='unit_box_0'>
      <pose frame=''>4.33276 -0.194304 0.5 0 -0 0</pose>
      <link name='link'>
        <inertial>
          <mass>1</mass>
          <inertia>
            <ixx>0.166667</ixx>
            <ixy>0</ixy>
            <ixz>0</ixz>
            <iyy>0.166667</iyy>
            <iyz>0</iyz>
            <izz>0.166667</izz>
          </inertia>
        </inertial>
        <collision name='collision'>
          <geometry>
            <box>
              <size>1 0.999994 1</size>
            </box>
          </geometry>
          <max_contacts>10</max_contacts>
          <surface>
            <contact>
              <ode/>
            </contact>
            <bounce/>
            <friction>
              <torsional>
                <ode/>
              </torsional>
              <ode/>
            </friction>
          </surface>
        </collision>
        <visual name='visual'>
          <geometry>
            <box>
              <size>1 0.999994 1</size>
            </box>
          </geometry>
          <material>
            <script>
              <name>Gazebo/Grey</name>
              <uri>file://media/materials/scripts/gazebo.material</uri>
            </script>
          </material>
        </visual>
        <self_collide>0</self_collide>
        <enable_wind>0</enable_wind>
        <kinematic>0</kinematic>
      </link>
    </model>
    <model name='unit_box_1'>
      <pose frame=''>-1.32643 -0.607937 0.5 0 -0 0</pose>
      <link name='link'>
        <inertial>
          <mass>1</mass>
          <inertia>
            <ixx>0.166667</ixx>
            <ixy>0</ixy>
            <ixz>0</ixz>
            <iyy>0.166667</iyy>
            <iyz>0</iyz>
            <izz>0.166667</izz>
          </inertia>
        </inertial>
        <collision name='collision'>
          <geometry>
            <box>
              <size>1 1 1</size>
            </box>
          </geometry>
          <max_contacts>10</max_contacts>
          <surface>
            <contact>
              <ode/>
            </contact>
            <bounce/>
            <friction>
              <torsional>
                <ode/>
              </torsional>
              <ode/>
            </friction>
          </surface>
        </collision>
        <visual name='visual'>
          <geometry>
            <box>
              <size>1 1 1</size>
            </box>
          </geometry>
          <material>
            <script>
              <name>Gazebo/Grey</name>
              <uri>file://media/materials/scripts/gazebo.material</uri>
            </script>
          </material>
        </visual>
        <self_collide>0</self_collide>
        <enable_wind>0</enable_wind>
        <kinematic>0</kinematic>
      </link>
    </model>
    <model name='unit_box_clone_0'>
      <pose frame=''>1.2082 4.33041 0.996637 0 -0.001216 -5.1e-05</pose>
      <link name='link'>
        <inertial>
          <mass>1</mass>
          <inertia>
            <ixx>0.166667</ixx>
            <ixy>0</ixy>
            <ixz>0</ixz>
            <iyy>0.166667</iyy>
            <iyz>0</iyz>
            <izz>0.166667</izz>
          </inertia>
        </inertial>
        <collision name='collision'>
          <geometry>
            <box>
              <size>5.53485 0.999995 1</size>
            </box>
          </geometry>
          <max_contacts>10</max_contacts>
          <surface>
            <contact>
              <ode/>
            </contact>
            <bounce/>
            <friction>
              <torsional>
                <ode/>
              </torsional>
              <ode/>
            </friction>
          </surface>
        </collision>
        <visual name='visual'>
          <geometry>
            <box>
              <size>5.53485 0.999995 1</size>
            </box>
          </geometry>
          <material>
            <script>
              <name>Gazebo/Grey</name>
              <uri>file://media/materials/scripts/gazebo.material</uri>
            </script>
          </material>
        </visual>
        <self_collide>0</self_collide>
        <enable_wind>0</enable_wind>
        <kinematic>0</kinematic>
      </link>
    </model>
    <model name='unit_box_clone_0_clone'>
      <pose frame=''>1.95972 -0.284104 0.999995 2e-06 -7e-06 -0.009715</pose>
      <link name='link'>
        <inertial>
          <mass>1</mass>
          <inertia>
            <ixx>0.166667</ixx>
            <ixy>0</ixy>
            <ixz>0</ixz>
            <iyy>0.166667</iyy>
            <iyz>0</iyz>
            <izz>0.166667</izz>
          </inertia>
        </inertial>
        <collision name='collision'>
          <geometry>
            <box>
              <size>1.49069 0.066925 1</size>
            </box>
          </geometry>
          <max_contacts>10</max_contacts>
          <surface>
            <contact>
              <ode/>
            </contact>
            <bounce/>
            <friction>
              <torsional>
                <ode/>
              </torsional>
              <ode/>
            </friction>
          </surface>
        </collision>
        <visual name='visual'>
          <geometry>
            <box>
              <size>1.49069 0.066925 1</size>
            </box>
          </geometry>
          <material>
            <script>
              <name>Gazebo/Grey</name>
              <uri>file://media/materials/scripts/gazebo.material</uri>
            </script>
          </material>
        </visual>
        <self_collide>0</self_collide>
        <enable_wind>0</enable_wind>
        <kinematic>0</kinematic>
      </link>
    </model>
    <state world_name='default'>
      <sim_time>455 663000000</sim_time>
      <real_time>1007 612452954</real_time>
      <wall_time>1589545771 61389729</wall_time>
      <iterations>455663</iterations>
      <model name='car'>
        <pose frame=''>-0.076065 -1.4e-05 0.524999 -1e-06 0.000837 3.13667</pose>
        <scale>1 1 1</scale>
        <link name='base_footprint'>
          <pose frame=''>-0.076065 -1.4e-05 0.524999 -1e-06 0.000837 3.13667</pose>
          <velocity>3e-06 8e-06 5e-06 0.000286 -8.9e-05 0.000129</velocity>
          <acceleration>-0.000313 -0.030664 -0.011092 0.052656 -0.086091 0.1722</acceleration>
          <wrench>-0.001191 -0.116522 -0.042151 0 -0 0</wrench>
        </link>
        <link name='steer_fl'>
          <pose frame=''>-0.375442 0.12996 0.540099 -1e-06 0.000837 3.13667</pose>
          <velocity>7e-06 0.001172 0.001205 -0.000354 -8.6e-05 0.000227</velocity>
          <acceleration>0.008817 2.9128 2.46613 -1.54816 -0.077668 0.313097</acceleration>
          <wrench>9e-06 0.002913 0.002466 0 -0 0</wrench>
        </link>
        <link name='steer_fr'>
          <pose frame=''>-0.376705 -0.127038 0.540098 1e-06 0.000838 3.13667</pose>
          <velocity>-1.3e-05 -0.00168 -0.00121 0.001251 -9.7e-05 -0.000186</velocity>
          <acceleration>-0.005653 -2.22927 -1.27726 1.38782 -0.097881 -0.407291</acceleration>
          <wrench>-6e-06 -0.002229 -0.001277 0 -0 0</wrench>
        </link>
        <link name='wheel_fl'>
          <pose frame=''>-0.375442 0.12996 0.54 1.57078 -1.1889 3.13669</pose>
          <velocity>1e-06 0.000861 0.000873 -0.021537 2.5e-05 7.5e-05</velocity>
          <acceleration>0.001232 2.15495 1.77432 2.52643 0.111742 0.256243</acceleration>
          <wrench>6.9e-05 0.120677 0.099362 0 -0 0</wrench>
        </link>
        <link name='wheel_fr'>
          <pose frame=''>-0.376705 -0.127038 0.539999 1.57077 -0.283157 3.13668</pose>
          <velocity>-4e-06 -0.001264 -0.000887 0.031754 -3e-06 -0.000268</velocity>
          <acceleration>0.00292 -1.6834 -0.930166 -1.74919 0.018222 -0.543919</acceleration>
          <wrench>0.000164 -0.094271 -0.052089 0 -0 0</wrench>
        </link>
        <link name='wheel_rl'>
          <pose frame=''>-0.075446 0.128484 0.54 1.57089 1.3884 3.13676</pose>
          <velocity>-1.5e-05 -0 -1e-06 7e-06 -0.000364 3.4e-05</velocity>
          <acceleration>-0.019483 -0.007633 -0.034365 -0.230137 -0.213727 0.129463</acceleration>
          <wrench>-0.001091 -0.000427 -0.001924 0 -0 0</wrench>
        </link>
        <link name='wheel_rr'>
          <pose frame=''>-0.076709 -0.128513 0.54 1.57095 1.45143 3.13682</pose>
          <velocity>1.8e-05 5e-06 1e-05 -0.000117 0.000457 3.5e-05</velocity>
          <acceleration>0.02428 -0.002724 0.037397 -0.355954 0.273902 0.13011</acceleration>
          <wrench>0.00136 -0.000153 0.002094 0 -0 0</wrench>
        </link>
      </model>
      <model name='my_ground_plane'>
        <pose frame=''>0 -0 0 0 -0 0</pose>
        <scale>1 1 1</scale>
        <link name='link'>
          <pose frame=''>1.529 -0.219 0.5 0 -0 3.139</pose>
          <velocity>0 0 0 0 -0 0</velocity>
          <acceleration>0 0 0 0 -0 0</acceleration>
          <wrench>0 0 0 0 -0 0</wrench>
        </link>
      </model>
      <model name='unit_box'>
        <pose frame=''>2.04182 1.2759 0.996637 0 0.001216 5.1e-05</pose>
        <scale>5.53489 1 1</scale>
        <link name='link'>
          <pose frame=''>2.04182 1.2759 0.996637 0 0.001216 5.1e-05</pose>
          <velocity>0.007303 0 -0.174118 0 0.066546 0</velocity>
          <acceleration>9.8 6e-06 -0 -0.000109 1.14484 -0</acceleration>
          <wrench>9.8 6e-06 -0 0 -0 0</wrench>
        </link>
      </model>
      <model name='unit_box_0'>
        <pose frame=''>4.28072 -0.143545 1 0 -0 0</pose>
        <scale>1 1.81449 1</scale>
        <link name='link'>
          <pose frame=''>4.28072 -0.143545 1 0 -0 0</pose>
          <velocity>0 0 0 0 -0 0</velocity>
          <acceleration>-9.45433 -0.061583 9.48369 0.121938 -0.079144 -0.001038</acceleration>
          <wrench>-9.45433 -0.061583 9.48369 0 -0 0</wrench>
        </link>
      </model>
      <model name='unit_box_1'>
        <pose frame=''>-1.22393 -0.980151 0.999974 2.4e-05 -0 -0.000875</pose>
        <scale>1 2.17104 1</scale>
        <link name='link'>
          <pose frame=''>-1.22393 -0.980151 0.999974 2.4e-05 -0 -0.000875</pose>
          <velocity>0 0 0 0 -0 0</velocity>
          <acceleration>-0.009053 -9.8 -0 3.01027 -0.030104 -0</acceleration>
          <wrench>-0.009053 -9.8 -0 0 -0 0</wrench>
        </link>
      </model>
      <model name='unit_box_clone'>
        <pose frame=''>2.03391 -1.55941 0.999996 -2e-06 -1e-06 -1.8e-05</pose>
        <scale>1.07256 1 1</scale>
        <link name='link'>
          <pose frame=''>2.03391 -1.55941 0.999996 -2e-06 -1e-06 -1.8e-05</pose>
          <velocity>0 0 0 0 -0 0</velocity>
          <acceleration>-0.15391 0.055217 -9.64609 2.84547 -1.05653 -2.68968</acceleration>
          <wrench>-0.15391 0.055217 -9.64609 0 -0 0</wrench>
        </link>
      </model>
      <model name='unit_box_clone_0'>
        <pose frame=''>0.033316 -0.271407 1 0 0 -0.009716</pose>
        <scale>0.269328 0.066925 1</scale>
        <link name='link'>
          <pose frame=''>0.033316 -0.271407 1 0 0 -0.009716</pose>
          <velocity>0 0 0 0 -0 0</velocity>
          <acceleration>-7.15777 -0.662104 10.5124 -1.81812 -1.39247 3.14154</acceleration>
          <wrench>-7.15777 -0.662104 10.5124 0 -0 0</wrench>
        </link>
      </model>
      <model name='unit_box_clone_0_clone'>
        <pose frame=''>2.1521 -0.28597 0.99999 0 -1e-05 -0.009969</pose>
        <scale>1.27991 1 1</scale>
        <link name='link'>
          <pose frame=''>2.1521 -0.28597 0.99999 0 -1e-05 -0.009969</pose>
          <velocity>0 0 0 0 -0 0</velocity>
          <acceleration>-9.8 -0.223225 -0 -2.53319 -1.56619 -3.14159</acceleration>
          <wrench>-9.8 -0.223225 -0 0 -0 0</wrench>
        </link>
      </model>
      <light name='sun'>
        <pose frame=''>0 0 10 0 -0 0</pose>
      </light>
    </state>
  </world>
</sdf>
