<sdf version='1.6'>
  <world name='default'>
    <gui fullscreen='0'>
      <camera name='user_camera'>
        <pose frame=''>3.43418 -8.46154 10.3941 -0 1.0268 1.524</pose>
        <view_controller>orbit</view_controller>
        <projection_type>perspective</projection_type>
      </camera>
    </gui>
    <model name='my_ground_plane'>
      <static>1</static>
      <link name='link'>
        <collision name='collision'>
          <geometry>
            <plane>
              <normal>0 0 1</normal>
              <size>4.5 1.6875</size>
            </plane>
          </geometry>
          <surface>
            <friction>
              <ode>
                <mu>100</mu>
                <mu2>50</mu2>
              </ode>
              <torsional>
                <ode/>
              </torsional>
            </friction>
            <contact>
              <ode/>
            </contact>
            <bounce/>
          </surface>
          <max_contacts>10</max_contacts>
        </collision>
        <visual name='visual'>
          <cast_shadows>0</cast_shadows>
          <geometry>
            <plane>
              <normal>0 0 1</normal>
              <size>4.5 1.6875</size>
            </plane>
          </geometry>
          <material>
            <script>
              <uri>model://my_ground_plane/materials/scripts</uri>
              <uri>model://my_ground_plane/materials/textures</uri>
              <name>MyGroundPlane/Image</name>
            </script>
          </material>
        </visual>
        <self_collide>0</self_collide>
        <enable_wind>0</enable_wind>
        <kinematic>0</kinematic>
      </link>
    </model>
    <light name='sun' type='directional'>
      <cast_shadows>1</cast_shadows>
      <pose frame=''>0 0 10 0 -0 0</pose>
      <diffuse>0.8 0.8 0.8 1</diffuse>
      <specular>0.2 0.2 0.2 1</specular>
      <attenuation>
        <range>1000</range>
        <constant>0.9</constant>
        <linear>0.01</linear>
        <quadratic>0.001</quadratic>
      </attenuation>
      <direction>-0.5 0.1 -0.9</direction>
    </light>
    <gravity>0 0 -9.8</gravity>
    <magnetic_field>6e-06 2.3e-05 -4.2e-05</magnetic_field>
    <atmosphere type='adiabatic'/>
    <physics name='default_physics' default='0' type='ode'>
      <max_step_size>0.001</max_step_size>
      <real_time_factor>1</real_time_factor>
      <real_time_update_rate>1000</real_time_update_rate>
    </physics>
    <scene>
      <ambient>0.4 0.4 0.4 1</ambient>
      <background>0.7 0.7 0.7 1</background>
      <shadows>1</shadows>
    </scene>
    <audio>
      <device>default</device>
    </audio>
    <wind/>
    <spherical_coordinates>
      <surface_model>EARTH_WGS84</surface_model>
      <latitude_deg>0</latitude_deg>
      <longitude_deg>0</longitude_deg>
      <elevation>0</elevation>
      <heading_deg>0</heading_deg>
    </spherical_coordinates>
    <model name='car'>
      <link name='base_footprint'>
        <pose frame=''>0 0 0 0 -0 0</pose>
        <inertial>
          <pose frame=''>0.149737 0 0.043684 0 -0 0</pose>
          <mass>3.8</mass>
          <inertia>
            <ixx>0.0186107</ixx>
            <ixy>0</ixy>
            <ixz>0.000136316</ixz>
            <iyy>0.07526</iyy>
            <iyz>0</iyz>
            <izz>0.0885056</izz>
          </inertia>
        </inertial>
        <collision name='base_footprint_fixed_joint_lump__base_center_collision'>
          <pose frame=''>0.15 0 0.04 0 -0 0</pose>
          <geometry>
            <box>
              <size>0.485 0.227 0.05</size>
            </box>
          </geometry>
          <surface>
            <contact>
              <ode/>
            </contact>
            <friction>
              <ode/>
              <torsional>
                <ode/>
              </torsional>
            </friction>
            <bounce/>
          </surface>
          <max_contacts>10</max_contacts>
        </collision>
        <collision name='base_footprint_fixed_joint_lump__laser_frame_collision_1'>
          <pose frame=''>0.14 0 0.18 0 -0 0</pose>
          <geometry>
            <cylinder>
              <length>0.02</length>
              <radius>0.04</radius>
            </cylinder>
          </geometry>
          <surface>
            <contact>
              <ode/>
            </contact>
            <friction>
              <ode/>
              <torsional>
                <ode/>
              </torsional>
            </friction>
            <bounce/>
          </surface>
          <max_contacts>10</max_contacts>
        </collision>
        <visual name='base_footprint_fixed_joint_lump__base_center_visual'>
          <pose frame=''>0.15 0 0.04 0 -0 0</pose>
          <geometry>
            <box>
              <size>0.485 0.227 0.05</size>
            </box>
          </geometry>
          <material>
            <script>
              <name>Gazebo/Orange</name>
              <uri>file://media/materials/scripts/gazebo.material</uri>
            </script>
          </material>
        </visual>
        <visual name='base_footprint_fixed_joint_lump__laser_frame_visual_1'>
          <pose frame=''>0.14 0 0.18 0 -0 0</pose>
          <geometry>
            <cylinder>
              <length>0.02</length>
              <radius>0.04</radius>
            </cylinder>
          </geometry>
          <material>
            <script>
              <name>Gazebo/Black</name>
              <uri>file://media/materials/scripts/gazebo.material</uri>
            </script>
          </material>
        </visual>
        <velocity_decay/>
        <velocity_decay/>
        <velocity_decay/>
        <gravity>1</gravity>
        <velocity_decay/>
        <sensor name='head_hokuyo_sensor' type='ray'>
          <visualize>1</visualize>
          <update_rate>7.5</update_rate>
          <ray>
            <scan>
              <horizontal>
                <samples>360</samples>
                <resolution>1</resolution>
                <min_angle>-3.14159</min_angle>
                <max_angle>3.14159</max_angle>
              </horizontal>
              <vertical>
                <samples>1</samples>
                <min_angle>0</min_angle>
                <max_angle>0</max_angle>
              </vertical>
            </scan>
            <range>
              <min>0.15</min>
              <max>10</max>
              <resolution>0.01</resolution>
            </range>
            <noise>
              <type>gaussian</type>
              <mean>0</mean>
              <stddev>0.01</stddev>
            </noise>
          </ray>
          <plugin name='gazebo_ros_head_hokuyo_controller' filename='libgazebo_ros_laser.so'>
            <topicName>/scan</topicName>
            <frameName>laser_frame</frameName>
            <robotNamespace>/</robotNamespace>
          </plugin>
          <pose frame=''>0.14 0 0.18 0 -0 0</pose>
        </sensor>
        <self_collide>0</self_collide>
        <enable_wind>0</enable_wind>
        <kinematic>0</kinematic>
      </link>
      <link name='steer_fl'>
        <pose frame=''>0.3 -0.1285 0.015 0 -0 0</pose>
        <inertial>
          <pose frame=''>0 0 0 0 -0 0</pose>
          <mass>0.001</mass>
          <inertia>
            <ixx>0.001</ixx>
            <ixy>0</ixy>
            <ixz>0</ixz>
            <iyy>0.001</iyy>
            <iyz>0</iyz>
            <izz>0.001</izz>
          </inertia>
        </inertial>
        <self_collide>0</self_collide>
        <enable_wind>0</enable_wind>
        <kinematic>0</kinematic>
      </link>
      <joint name='fl_steer_joint' type='revolute'>
        <child>steer_fl</child>
        <parent>base_footprint</parent>
        <axis>
          <xyz>0 0 1</xyz>
          <limit>
            <lower>-0.785398</lower>
            <upper>0.785398</upper>
            <effort>0</effort>
            <velocity>0</velocity>
          </limit>
          <dynamics>
            <spring_reference>0</spring_reference>
            <spring_stiffness>0</spring_stiffness>
          </dynamics>
          <use_parent_model_frame>1</use_parent_model_frame>
        </axis>
      </joint>
      <link name='wheel_fl'>
        <pose frame=''>0.3 -0.1285 0.015 1.5708 -0 0</pose>
        <inertial>
          <pose frame=''>0 0 0 0 -0 0</pose>
          <mass>0.056</mass>
          <inertia>
            <ixx>2.66e-05</ixx>
            <ixy>0</ixy>
            <ixz>0</ixz>
            <iyy>2.66e-05</iyy>
            <iyz>0</iyz>
            <izz>4.48e-05</izz>
          </inertia>
        </inertial>
        <collision name='wheel_fl_collision'>
          <pose frame=''>0 0 0 0 -0 0</pose>
          <geometry>
            <cylinder>
              <length>0.03</length>
              <radius>0.04</radius>
            </cylinder>
          </geometry>
          <surface>
            <contact>
              <ode>
                <kp>1e+07</kp>
                <kd>1</kd>
              </ode>
            </contact>
            <friction>
              <ode>
                <mu>1.75</mu>
                <mu2>1.75</mu2>
              </ode>
              <torsional>
                <ode/>
              </torsional>
            </friction>
            <bounce/>
          </surface>
          <max_contacts>10</max_contacts>
        </collision>
        <visual name='wheel_fl_visual'>
          <pose frame=''>0 0 0 0 -0 0</pose>
          <geometry>
            <cylinder>
              <length>0.03</length>
              <radius>0.04</radius>
            </cylinder>
          </geometry>
          <material>
            <script>
              <name>Gazebo/Black</name>
              <uri>file://media/materials/scripts/gazebo.material</uri>
            </script>
          </material>
        </visual>
        <gravity>1</gravity>
        <velocity_decay/>
        <self_collide>0</self_collide>
        <enable_wind>0</enable_wind>
        <kinematic>0</kinematic>
      </link>
      <joint name='fl_speed_joint' type='revolute'>
        <child>wheel_fl</child>
        <parent>steer_fl</parent>
        <axis>
          <xyz>0 1 -0</xyz>
          <limit>
            <lower>-1e+16</lower>
            <upper>1e+16</upper>
          </limit>
          <dynamics>
            <spring_reference>0</spring_reference>
            <spring_stiffness>0</spring_stiffness>
          </dynamics>
          <use_parent_model_frame>1</use_parent_model_frame>
        </axis>
      </joint>
      <link name='steer_fr'>
        <pose frame=''>0.3 0.1285 0.015 0 -0 0</pose>
        <inertial>
          <pose frame=''>0 0 0 0 -0 0</pose>
          <mass>0.001</mass>
          <inertia>
            <ixx>0.001</ixx>
            <ixy>0</ixy>
            <ixz>0</ixz>
            <iyy>0.001</iyy>
            <iyz>0</iyz>
            <izz>0.001</izz>
          </inertia>
        </inertial>
        <self_collide>0</self_collide>
        <enable_wind>0</enable_wind>
        <kinematic>0</kinematic>
      </link>
      <joint name='fr_steer_joint' type='revolute'>
        <child>steer_fr</child>
        <parent>base_footprint</parent>
        <axis>
          <xyz>0 0 1</xyz>
          <limit>
            <lower>-0.785398</lower>
            <upper>0.785398</upper>
            <effort>0</effort>
            <velocity>0</velocity>
          </limit>
          <dynamics>
            <spring_reference>0</spring_reference>
            <spring_stiffness>0</spring_stiffness>
          </dynamics>
          <use_parent_model_frame>1</use_parent_model_frame>
        </axis>
      </joint>
      <link name='wheel_fr'>
        <pose frame=''>0.3 0.1285 0.015 1.5708 -0 0</pose>
        <inertial>
          <pose frame=''>0 0 0 0 -0 0</pose>
          <mass>0.056</mass>
          <inertia>
            <ixx>2.66e-05</ixx>
            <ixy>0</ixy>
            <ixz>0</ixz>
            <iyy>2.66e-05</iyy>
            <iyz>0</iyz>
            <izz>4.48e-05</izz>
          </inertia>
        </inertial>
        <collision name='wheel_fr_collision'>
          <pose frame=''>0 0 0 0 -0 0</pose>
          <geometry>
            <cylinder>
              <length>0.03</length>
              <radius>0.04</radius>
            </cylinder>
          </geometry>
          <surface>
            <contact>
              <ode>
                <kp>1e+07</kp>
                <kd>1</kd>
              </ode>
            </contact>
            <friction>
              <ode>
                <mu>1.75</mu>
                <mu2>1.75</mu2>
              </ode>
              <torsional>
                <ode/>
              </torsional>
            </friction>
            <bounce/>
          </surface>
          <max_contacts>10</max_contacts>
        </collision>
        <visual name='wheel_fr_visual'>
          <pose frame=''>0 0 0 0 -0 0</pose>
          <geometry>
            <cylinder>
              <length>0.03</length>
              <radius>0.04</radius>
            </cylinder>
          </geometry>
          <material>
            <script>
              <name>Gazebo/Black</name>
              <uri>file://media/materials/scripts/gazebo.material</uri>
            </script>
          </material>
        </visual>
        <gravity>1</gravity>
        <velocity_decay/>
        <self_collide>0</self_collide>
        <enable_wind>0</enable_wind>
        <kinematic>0</kinematic>
      </link>
      <joint name='fr_speed_joint' type='revolute'>
        <child>wheel_fr</child>
        <parent>steer_fr</parent>
        <axis>
          <xyz>0 1 -0</xyz>
          <limit>
            <lower>-1e+16</lower>
            <upper>1e+16</upper>
          </limit>
          <dynamics>
            <spring_reference>0</spring_reference>
            <spring_stiffness>0</spring_stiffness>
          </dynamics>
          <use_parent_model_frame>1</use_parent_model_frame>
        </axis>
      </joint>
      <link name='wheel_rl'>
        <pose frame=''>0 -0.1285 0.015 1.5708 -0 0</pose>
        <inertial>
          <pose frame=''>0 0 0 0 -0 0</pose>
          <mass>0.056</mass>
          <inertia>
            <ixx>2.66e-05</ixx>
            <ixy>0</ixy>
            <ixz>0</ixz>
            <iyy>2.66e-05</iyy>
            <iyz>0</iyz>
            <izz>4.48e-05</izz>
          </inertia>
        </inertial>
        <collision name='wheel_rl_collision'>
          <pose frame=''>0 0 0 0 -0 0</pose>
          <geometry>
            <cylinder>
              <length>0.03</length>
              <radius>0.04</radius>
            </cylinder>
          </geometry>
          <surface>
            <contact>
              <ode>
                <kp>1e+07</kp>
                <kd>1</kd>
              </ode>
            </contact>
            <friction>
              <ode>
                <mu>1.75</mu>
                <mu2>1.75</mu2>
              </ode>
              <torsional>
                <ode/>
              </torsional>
            </friction>
            <bounce/>
          </surface>
          <max_contacts>10</max_contacts>
        </collision>
        <visual name='wheel_rl_visual'>
          <pose frame=''>0 0 0 0 -0 0</pose>
          <geometry>
            <cylinder>
              <length>0.03</length>
              <radius>0.04</radius>
            </cylinder>
          </geometry>
          <material>
            <script>
              <name>Gazebo/Black</name>
              <uri>file://media/materials/scripts/gazebo.material</uri>
            </script>
          </material>
        </visual>
        <gravity>1</gravity>
        <velocity_decay/>
        <self_collide>0</self_collide>
        <enable_wind>0</enable_wind>
        <kinematic>0</kinematic>
      </link>
      <joint name='rl_speed_joint' type='revolute'>
        <child>wheel_rl</child>
        <parent>base_footprint</parent>
        <axis>
          <xyz>0 1 -0</xyz>
          <limit>
            <lower>-1e+16</lower>
            <upper>1e+16</upper>
          </limit>
          <dynamics>
            <spring_reference>0</spring_reference>
            <spring_stiffness>0</spring_stiffness>
          </dynamics>
          <use_parent_model_frame>1</use_parent_model_frame>
        </axis>
      </joint>
      <link name='wheel_rr'>
        <pose frame=''>0 0.1285 0.015 1.5708 -0 0</pose>
        <inertial>
          <pose frame=''>0 0 0 0 -0 0</pose>
          <mass>0.056</mass>
          <inertia>
            <ixx>2.66e-05</ixx>
            <ixy>0</ixy>
            <ixz>0</ixz>
            <iyy>2.66e-05</iyy>
            <iyz>0</iyz>
            <izz>4.48e-05</izz>
          </inertia>
        </inertial>
        <collision name='wheel_rr_collision'>
          <pose frame=''>0 0 0 0 -0 0</pose>
          <geometry>
            <cylinder>
              <length>0.03</length>
              <radius>0.04</radius>
            </cylinder>
          </geometry>
          <surface>
            <contact>
              <ode>
                <kp>1e+07</kp>
                <kd>1</kd>
              </ode>
            </contact>
            <friction>
              <ode>
                <mu>1.75</mu>
                <mu2>1.75</mu2>
              </ode>
              <torsional>
                <ode/>
              </torsional>
            </friction>
            <bounce/>
          </surface>
          <max_contacts>10</max_contacts>
        </collision>
        <visual name='wheel_rr_visual'>
          <pose frame=''>0 0 0 0 -0 0</pose>
          <geometry>
            <cylinder>
              <length>0.03</length>
              <radius>0.04</radius>
            </cylinder>
          </geometry>
          <material>
            <script>
              <name>Gazebo/Black</name>
              <uri>file://media/materials/scripts/gazebo.material</uri>
            </script>
          </material>
        </visual>
        <gravity>1</gravity>
        <velocity_decay/>
        <self_collide>0</self_collide>
        <enable_wind>0</enable_wind>
        <kinematic>0</kinematic>
      </link>
      <joint name='rr_speed_joint' type='revolute'>
        <child>wheel_rr</child>
        <parent>base_footprint</parent>
        <axis>
          <xyz>0 1 -0</xyz>
          <limit>
            <lower>-1e+16</lower>
            <upper>1e+16</upper>
          </limit>
          <dynamics>
            <spring_reference>0</spring_reference>
            <spring_stiffness>0</spring_stiffness>
          </dynamics>
          <use_parent_model_frame>1</use_parent_model_frame>
        </axis>
      </joint>
      <static>0</static>
      <plugin name='wr8_interface_plugin' filename='libwr8_interface_plugin.so'>
        <robotName/>
        <pubTf>1</pubTf>
        <tfFreq>100.0</tfFreq>
        <maxSteerRad>0.523598775598</maxSteerRad>
        <wheelbase>0.3</wheelbase>
        <wheelRadius>0.04</wheelRadius>
        <trackWidth>0.257</trackWidth>
        <robotNamespace>/</robotNamespace>
      </plugin>
      <plugin name='joint_state_publisher' filename='libgazebo_ros_joint_state_publisher.so'>
        <robotNamespace/>
        <jointName>fl_steer_joint, fr_steer_joint, fl_speed_joint, fr_speed_joint, rl_speed_joint, rr_speed_joint</jointName>
        <updateRate>100</updateRate>
        <alwaysOn>1</alwaysOn>
      </plugin>
      <pose frame=''>2.029 -0.219 0.5 0 -0 3.139</pose>
    </model>
    <model name='unit_box'>
      <pose frame=''>-0.906905 0.081655 0.5 0 -0 0</pose>
      <link name='link'>
        <inertial>
          <mass>1</mass>
          <inertia>
            <ixx>0.166667</ixx>
            <ixy>0</ixy>
            <ixz>0</ixz>
            <iyy>0.166667</iyy>
            <iyz>0</iyz>
            <izz>0.166667</izz>
          </inertia>
        </inertial>
        <collision name='collision'>
          <geometry>
            <box>
              <size>1 1 1</size>
            </box>
          </geometry>
          <max_contacts>10</max_contacts>
          <surface>
            <contact>
              <ode/>
            </contact>
            <bounce/>
            <friction>
              <torsional>
                <ode/>
              </torsional>
              <ode/>
            </friction>
          </surface>
        </collision>
        <visual name='visual'>
          <geometry>
            <box>
              <size>1 1 1</size>
            </box>
          </geometry>
          <material>
            <script>
              <name>Gazebo/Grey</name>
              <uri>file://media/materials/scripts/gazebo.material</uri>
            </script>
          </material>
        </visual>
        <self_collide>0</self_collide>
        <enable_wind>0</enable_wind>
        <kinematic>0</kinematic>
      </link>
    </model>
    <state world_name='default'>
      <sim_time>71 987000000</sim_time>
      <real_time>199 359060932</real_time>
      <wall_time>1589127925 807653594</wall_time>
      <iterations>71987</iterations>
      <model name='car'>
        <pose frame=''>2.02835 -0.218924 0.024999 -1e-06 0.000837 3.13946</pose>
        <scale>1 1 1</scale>
        <link name='base_footprint'>
          <pose frame=''>2.02835 -0.218924 0.024999 -1e-06 0.000837 3.13946</pose>
          <velocity>6e-06 3.4e-05 3e-06 0.001021 -0.000148 0.000184</velocity>
          <acceleration>-0.000355 -0.090577 -0.042607 1.38339 -0.292196 0.459822</acceleration>
          <wrench>-0.001351 -0.344192 -0.161908 0 -0 0</wrench>
        </link>
        <link name='steer_fl'>
          <pose frame=''>1.72861 -0.089786 0.040098 -2e-06 0.000837 3.13946</pose>
          <velocity>1.2e-05 -0.001751 -0.001291 0.001973 -0.000152 0.000141</velocity>
          <acceleration>0.013643 -2.31644 -1.34982 2.65068 -0.293968 0.468873</acceleration>
          <wrench>1.4e-05 -0.002316 -0.00135 0 -0 0</wrench>
        </link>
        <link name='steer_fr'>
          <pose frame=''>1.72806 -0.346785 0.040098 1e-06 0.000838 3.13946</pose>
          <velocity>-3e-05 -0.001729 -0.001188 0.001911 -0.000148 -0.000136</velocity>
          <acceleration>-0.034622 -2.29104 -1.21487 2.56693 -0.290138 -0.140866</acceleration>
          <wrench>-3.5e-05 -0.002291 -0.001215 0 -0 0</wrench>
        </link>
        <link name='wheel_fl'>
          <pose frame=''>1.72861 -0.089785 0.039999 1.57074 1.0847 3.13941</pose>
          <velocity>3e-06 -0.001318 -0.000906 0.033089 5.2e-05 5.2e-05</velocity>
          <acceleration>-0.005009 -1.76586 -0.950894 0.314845 -0.119621 0.274457</acceleration>
          <wrench>-0.000281 -0.098888 -0.05325 0 -0 0</wrench>
        </link>
        <link name='wheel_fr'>
          <pose frame=''>1.72806 -0.346785 0.039999 1.57072 1.18667 3.13939</pose>
          <velocity>-1.4e-05 -0.001302 -0.0009 0.032695 -0.000263 -0.00023</velocity>
          <acceleration>-0.005687 -1.74798 -0.944208 -0.131864 -0.069318 -0.362833</acceleration>
          <wrench>-0.000318 -0.097887 -0.052876 0 -0 0</wrench>
        </link>
        <link name='wheel_rl'>
          <pose frame=''>2.02861 -0.090425 0.04 1.57081 -0.001183 3.13946</pose>
          <velocity>-1.9e-05 5e-06 0 -0.000114 -0.000464 4.5e-05</velocity>
          <acceleration>-0.048672 0.003023 0.043094 0.238527 -0.35977 0.531306</acceleration>
          <wrench>-0.002726 0.000169 0.002413 0 -0 0</wrench>
        </link>
        <link name='wheel_rr'>
          <pose frame=''>2.02806 -0.347424 0.04 1.57082 0.008396 3.13946</pose>
          <velocity>2.5e-05 1.7e-05 2e-06 -0.000415 0.000638 4.8e-05</velocity>
          <acceleration>0.064911 0.014882 -0.046262 -0.062808 0.294636 0.535716</acceleration>
          <wrench>0.003635 0.000833 -0.002591 0 -0 0</wrench>
        </link>
      </model>
      <model name='my_ground_plane'>
        <pose frame=''>0 0 0 0 -0 0</pose>
        <scale>1 1 1</scale>
        <link name='link'>
          <pose frame=''>0 0 0 0 -0 0</pose>
          <velocity>0 0 0 0 -0 0</velocity>
          <acceleration>0 0 0 0 -0 0</acceleration>
          <wrench>0 0 0 0 -0 0</wrench>
        </link>
      </model>
      <model name='unit_box'>
        <pose frame=''>-1.95513 0.038181 0.251073 9e-06 -2e-06 1.2e-05</pose>
        <scale>0.361511 1.51764 0.502161</scale>
        <link name='link'>
          <pose frame=''>-1.95513 0.038181 0.251073 9e-06 -2e-06 1.2e-05</pose>
          <velocity>0 0 0 0 -0 0</velocity>
          <acceleration>-0.530654 -2.22779 -7.11405 -0.551965 -1.02816 -3.14155</acceleration>
          <wrench>-0.530654 -2.22779 -7.11405 0 -0 0</wrench>
        </link>
      </model>
      <light name='sun'>
        <pose frame=''>0 0 10 0 -0 0</pose>
      </light>
    </state>
  </world>
</sdf>
